Workbook

Sheet Option_Portfolio
B3: # contracts | C3: option | D3: underlying | E3: K | F3: T (in years) | G3: σ (annual) | H3: risk free rate
B4: 7000 | C4: long put | D4: NESN | E4: 85 | F4: 0.5 | G4: 0.17 | H4: 0.01
B5: 2000 | C5: short call | D5: SREN | E5: 120 | F5: 0.5 | G5: 0.22 | H5: 0.01

Sheet Underlying_Assets
C2: Beta
B3: NSEN | C3: 0.75
B4: SREN | C4: 1.1
A7: date | C7: NSEN | D7: SREN | E7: P_SMI | F7: SMI | G7: CHF/USD | H7: R_NSEN | I7: R_SREN | J7: R_SMI | K7: R_CHF/USD
A8: 45232 | C8: 100.52 | D8: 100.4 | E8: 10591.979 | F8: 0.0083865592 | G8: 1.1034483 | H8: 0 | I8: 0 | J8: 0 | K8: 0
A9: 45233 | C9: 99.75 | D9: 99.26 | E9: 10579.672 | F9: -0.0011619935 | G9: 1.1131519 | H9: =(C9/C8)-1 -> -0.0076601671 | I9: =(D9/D8)-1 -> -0.011354582 | J9: =(E9/E8)-1 -> -0.0011619935 | K9: =(G9/G8)-1 -> 0.0087938873
A10: 45236 | C10: 99.87 | D10: 99.1 | E10: 10576.754 | F10: -0.00027577402 | G10: 1.1146408 | H10: =(C10/C9)-1 -> 0.0012030075 | I10: =(D10/D9)-1 -> -0.0016119283 | J10: =(E10/E9)-1 -> -0.00027577402 | K10: =(G10/G9)-1 -> 0.0013375533
A11: 45237 | C11: 99.62 | D11: 98.84 | E11: 10571.033 | F11: -0.00054094184 | G11: 1.1106793 | H11: =(C11/C10)-1 -> -0.0025032542 | I11: =(D11/D10)-1 -> -0.0026236125 | J11: =(E11/E10)-1 -> -0.00054094184 | K11: =(G11/G10)-1 -> -0.0035540597
A12: 45238 | C12: 99.07 | D12: 98.7 | E12: 10595.061 | F12: 0.0022730268 | G12: 1.1129661 | H12: =(C12/C11)-1 -> -0.0055209797 | I12: =(D12/D11)-1 -> -0.0014164306 | J12: =(E12/E11)-1 -> 0.0022730268 | K12: =(G12/G11)-1 -> 0.0020589202
A13: 45239 | C13: 99.91 | D13: 98.36 | E13: 10644.99 | F13: 0.0047124541 | G13: 1.1119142 | H13: =(C13/C12)-1 -> 0.0084788533 | I13: =(D13/D12)-1 -> -0.0034447822 | J13: =(E13/E12)-1 -> 0.0047124541 | K13: =(G13/G12)-1 -> -0.00094513211
A14: 45240 | C14: 99.38 | D14: 97.96 | E14: 10555.353 | F14: -0.0084204991 | G14: 1.1073583 | H14: =(C14/C13)-1 -> -0.0053047743 | I14: =(D14/D13)-1 -> -0.0040666938 | J14: =(E14/E13)-1 -> -0.0084204991 | K14: =(G14/G13)-1 -> -0.0040973485
A15: 45243 | C15: 98.9 | D15: 99.2 | E15: 10590.393 | F15: 0.0033195704 | G15: 1.1080946 | H15: =(C15/C14)-1 -> -0.0048299457 | I15: =(D15/D14)-1 -> 0.012658228 | J15: =(E15/E14)-1 -> 0.0033195704 | K15: =(G15/G14)-1 -> 0.00066491577
A16: 45244 | C16: 99.4 | D16: 99.1 | E16: 10715.73 | F16: 0.011835031 | G16: 1.1208878 | H16: =(C16/C15)-1 -> 0.0050556117 | I16: =(D16/D15)-1 -> -0.0010080645 | J16: =(E16/E15)-1 -> 0.011835031 | K16: =(G16/G15)-1 -> 0.011545224
A17: 45245 | C17: 99.6 | D17: 99.14 | E17: 10708.195 | F17: -0.00070323644 | G17: 1.1284134 | H17: =(C17/C16)-1 -> 0.0020120724 | I17: =(D17/D16)-1 -> 0.00040363269 | J17: =(E17/E16)-1 -> -0.00070323644 | K17: =(G17/G16)-1 -> 0.0067139637
A18: 45246 | C18: 98.63 | D18: 99.06 | E18: 10643.069 | F18: -0.0060818873 | G18: 1.126824 | H18: =(C18/C17)-1 -> -0.0097389558 | I18: =(D18/D17)-1 -> -0.00080693968 | J18: =(E18/E17)-1 -> -0.0060818873 | K18: =(G18/G17)-1 -> -0.0014085263
A19: 45247 | C19: 98.99 | D19: 99.98 | E19: 10737.367 | F19: 0.0088601213 | G19: 1.1280316 | H19: =(C19/C18)-1 -> 0.0036500051 | I19: =(D19/D18)-1 -> 0.0092873006 | J19: =(E19/E18)-1 -> 0.0088601213 | K19: =(G19/G18)-1 -> 0.0010716847
A20: 45250 | C20: 98.29 | D20: 100.95 | E20: 10740.269 | F20: 0.00027018316 | G20: 1.1309019 | H20: =(C20/C19)-1 -> -0.0070714214 | I20: =(D20/D19)-1 -> 0.0097019404 | J20: =(E20/E19)-1 -> 0.00027018316 | K20: =(G20/G19)-1 -> 0.0025445209
... A365: 45772 | C365: 85.74 | D365: 144.8 | E365: 11942.049 | F365: 0.00020526309 | G365: 1.1347518 | H365: =(C365/C364)-1 -> -0.019441903 | I365: =(D365/D364)-1 -> 0.00034542314 | J365: =(E365/E364)-1 -> 0.0020526309 | K365: =(G365/G364)-1 -> 0.0048226986

Sheet FI_Portfolio
B3: # bonds | C3: maturity in years | D3: annual coupon
B4: 2000000 | C4: 1 | D4: zero | E4: 0
B5: -1500000 | C5: 3 | D5: 5 | E5: 5
B6: 4000000 | C6: 5 | D6: 2 | E6: 2
B9: Notes:
B10: Negative #bonds means you are short

Sheet TSIR
A1: date | B1: 1y | C1: 2y | D1: 3y | E1: 4y | F1: 5y | G1: 1y | H1: 2y | I1: 3y | J1: 4y | K1: 5y | L1: 1y | M1: 2y | N1: 3y | O1: 4y | P1: 5y
A2: 44200 | B2: 0.1 | C2: 0.11 | D2: 0.16 | E2: 0.26005084 | F2: 0.36 | G2: 0 | H2: 0 | I2: 0 | J2: 0 | K2: 0 | L2: =G2/B2 -> 0 | M2: =H2/C2 -> 0 | N2: =I2/D2 -> 0 | O2: =J2/E2 -> 0 | P2: =K2/F2 -> 0 | R2: YIELDS
A3: 44201 | B3: 0.1 | C3: 0.13 | D3: 0.17 | E3: 0.27536133 | F3: 0.38 | G3: =(B3-B2)/100 -> 0 | H3: =(C3-C2)/100 -> 0.0002 | I3: =(D3-D2)/100 -> 0.0001 | J3: =(E3-E2)/100 -> 0.00015310492 | K3: =(F3-F2)/100 -> 0.0002 | L3: =(B3/B2)-1 -> 0 | M3: =(C3/C2)-1 -> 0.18181818 | N3: =(D3/D2)-1 -> 0.0625 | O3: =(E3/E2)-1 -> 0.058874995 | P3: =(F3/F2)-1 -> 0.055555556 | R3: VARIATIONS
A4: 44202 | B4: 0.11 | C4: 0.14 | D4: 0.2 | E4: 0.31523797 | F4: 0.43 | G4: =(B4-B3)/100 -> 0.0001 | H4: =(C4-C3)/100 -> 0.0001 | I4: =(D4-D3)/100 -> 0.0003 | J4: =(E4-E3)/100 -> 0.00039876643 | K4: =(F4-F3)/100 -> 0.0005 | L4: =(B4/B3)-1 -> 0.1 | M4: =(C4/C3)-1 -> 0.076923077 | N4: =(D4/D3)-1 -> 0.17647059 | O4: =(E4/E3)-1 -> 0.1448157 | P4: =(F4/F3)-1 -> 0.13157895 | R4: RETURNS
A5: 44203 | B5: 0.11 | C5: 0.14 | D5: 0.22 | E5: 0.34002364 | F5: 0.46 | G5: =(B5-B4)/100 -> 0 | H5: =(C5-C4)/100 -> 0 | I5: =(D5-D4)/100 -> 0.0002 | J5: =(E5-E4)/100 -> 0.00024785673 | K5: =(F5-F4)/100 -> 0.0003 | L5: =(B5/B4)-1 -> 0 | M5: =(C5/C4)-1 -> 0 | N5: =(D5/D4)-1 -> 0.1 | O5: =(E5/E4)-1 -> 0.078625279 | P5: =(F5/F4)-1 -> 0.069767442
A6: 44204 | B6: 0.1 | C6: 0.14 | D6: 0.24 | E6: 0.36533805 | F6: 0.49 | G6: =(B6-B5)/100 -> -0.0001 | H6: =(C6-C5)/100 -> 0 | I6: =(D6-D5)/100 -> 0.0002 | J6: =(E6-E5)/100 -> 0.00025314409 | K6: =(F6-F5)/100 -> 0.0003 | L6: =(B6/B5)-1 -> -0.090909091 | M6: =(C6/C5)-1 -> 0 | N6: =(D6/D5)-1 -> 0.090909091 | O6: =(E6/E5)-1 -> 0.074448968 | P6: =(F6/F5)-1 -> 0.065217391
A7: 44207 | B7: 0.1 | C7: 0.14 | D7: 0.22 | E7: 0.36043964 | F7: 0.5 | G7: =(B7-B6)/100 -> 0 | H7: =(C7-C6)/100 -> 0 | I7: =(D7-D6)/100 -> -0.0002 | J7: =(E7-E6)/100 -> -4.8984104e-05 | K7: =(F7-F6)/100 -> 0.0001 | L7: =(B7/B6)-1 -> 0 | M7: =(C7/C6)-1 -> 0 | N7: =(D7/D6)-1 -> -0.083333333 | O7: =(E7/E6)-1 -> -0.013407885 | P7: =(F7/F6)-1 -> 0.020408163
A8: 44208 | B8: 0.11 | C8: 0.14 | D8: 0.23 | E8: 0.36541897 | F8: 0.5 | G8: =(B8-B7)/100 -> 0.0001 | H8: =(C8-C7)/100 -> 0 | I8: =(D8-D7)/100 -> 0.0001 | J8: =(E8-E7)/100 -> 4.9793222e-05 | K8: =(F8-F7)/100 -> 0 | L8: =(B8/B7)-1 -> 0.1 | M8: =(C8/C7)-1 -> 0 | N8: =(D8/D7)-1 -> 0.045454545 | O8: =(E8/E7)-1 -> 0.01381458 | P8: =(F8/F7)-1 -> 0
A9: 44209 | B9: 0.12 | C9: 0.14 | D9: 0.22 | E9: 0.35011298 | F9: 0.48 | G9: =(B9-B8)/100 -> 0.0001 | H9: =(C9-C8)/100 -> 0 | I9: =(D9-D8)/100 -> -0.0001 | J9: =(E9-E8)/100 -> -0.0001530599 | K9: =(F9-F8)/100 -> -0.0002 | L9: =(B9/B8)-1 -> 0.090909091 | M9: =(C9/C8)-1 -> 0 | N9: =(D9/D8)-1 -> -0.043478261 | O9: =(E9/E8)-1 -> -0.041886139 | P9: =(F9/F8)-1 -> -0.04
A10: 44210 | B10: 0.1 | C10: 0.16 | D10: 0.23 | E10: 0.36044743 | F10: 0.49 | G10: =(B10-B9)/100 -> -0.0002 | H10: =(C10-C9)/100 -> 0.0002 | I10: =(D10-D9)/100 -> 0.0001 | J10: =(E10-E9)/100 -> 0.00010334455 | K10: =(F10-F9)/100 -> 0.0001 | L10: =(B10/B9)-1 -> -0.16666667 | M10: =(C10/C9)-1 -> 0.14285714 | N10: =(D10/D9)-1 -> 0.045454545 | O10: =(E10/E9)-1 -> 0.029517486 | P10: =(F10/F9)-1 -> 0.020833333
A11: 44211 | B11: 0.1 | C11: 0.13 | D11: 0.2 | E11: 0.33023905 | F11: 0.46 | G11: =(B11-B10)/100 -> 0 | H11: =(C11-C10)/100 -> -0.0003 | I11: =(D11-D10)/100 -> -0.0003 | J11: =(E11-E10)/100 -> -0.00030208377 | K11: =(F11-F10)/100 -> -0.0003 | L11: =(B11/B10)-1 -> 0 | M11: =(C11/C10)-1 -> -0.1875 | N11: =(D11/D10)-1 -> -0.13043478 | O11: =(E11/E10)-1 -> -0.083807997 | P11: =(F11/F10)-1 -> -0.06122449
A12: 44215 | B12: 0.1 | C12: 0.14 | D12: 0.21 | E12: 0.33025798 | F12: 0.45 | G12: =(B12-B11)/100 -> 0 | H12: =(C12-C11)/100 -> 0.0001 | I12: =(D12-D11)/100 -> 0.0001 | J12: =(E12-E11)/100 -> 1.8926313e-07 | K12: =(F12-F11)/100 -> -0.0001 | L12: =(B12/B11)-1 -> 0 | M12: =(C12/C11)-1 -> 0.076923077 | N12: =(D12/D11)-1 -> 0.05 | O12: =(E12/E11)-1 -> 5.7310948e-05 | P12: =(F12/F11)-1 -> -0.02173913
A13: 44216 | B13: 0.1 | C13: 0.13 | D13: 0.19 | E13: 0.32026831 | F13: 0.45 | G13: =(B13-B12)/100 -> 0 | H13: =(C13-C12)/100 -> -0.0001 | I13: =(D13-D12)/100 -> -0.0002 | J13: =(E13-E12)/100 -> -9.9896685e-05 | K13: =(F13-F12)/100 -> 0 | L13: =(B13/B12)-1 -> 0 | M13: =(C13/C12)-1 -> -0.071428571 | N13: =(D13/D12)-1 -> -0.095238095 | O13: =(E13/E12)-1 -> -0.030248076 | P13: =(F13/F12)-1 -> 0
A14: 44217 | B14: 0.1 | C14: 0.13 | D14: 0.19 | E14: 0.32042425 | F14: 0.45 | G14: =(B14-B13)/100 -> 0 | H14: =(C14-C13)/100 -> 0 | I14: =(D14-D13)/100 -> 0 | J14: =(E14-E13)/100 -> 1.5593777e-06 | K14: =(F14-F13)/100 -> 0 | L14: =(B14/B13)-1 -> 0 | M14: =(C14/C13)-1 -> 0 | N14: =(D14/D13)-1 -> 0 | O14: =(E14/E13)-1 -> 0.00048689728 | P14: =(F14/F13)-1 -> 0
A15: 44218 | B15: 0.1 | C15: 0.13 | D15: 0.19 | E15: 0.31548957 | F15: 0.44 | G15: =(B15-B14)/100 -> 0 | H15: =(C15-C14)/100 -> 0 | I15: =(D15-D14)/100 -> 0 | J15: =(E15-E14)/100 -> -4.9346745e-05 | K15: =(F15-F14)/100 -> -0.0001 | L15: =(B15/B14)-1 -> 0 | M15: =(C15/C14)-1 -> 0 | N15: =(D15/D14)-1 -> 0 | O15: =(E15/E14)-1 -> -0.01540044 | P15: =(F15/F14)-1 -> -0.022222222
A16: 44221 | B16: 0.1 | C16: 0.13 | D16: 0.17 | E16: 0.29528304 | F16: 0.42 | G16: =(B16-B15)/100 -> 0 | H16: =(C16-C15)/100 -> 0 | I16: =(D16-D15)/100 -> -0.0002 | J16: =(E16-E15)/100 -> -0.00020206532 | K16: =(F16-F15)/100 -> -0.0002 | L16: =(B16/B15)-1 -> 0 | M16: =(C16/C15)-1 -> 0 | N16: =(D16/D15)-1 -> -0.10526316 | O16: =(E16/E15)-1 -> -0.064048178 | P16: =(F16/F15)-1 -> -0.045454545
... A603: 45072 | B603: 5.25 | C603: 4.54 | D603: 4.23 | E603: 4.0319 | F603: 3.92 | G603: =(B603-B602)/100 -> 0.0001 | H603: =(C603-C602)/100 -> 0.0004 | I603: =(D603-D602)/100 -> 0.0002 | J603: =(E603-E602)/100 -> 0.000437 | K603: =(F603-F602)/100 -> 0.0002 | L603: =(B603/B602)-1 -> 0.0019083969 | M603: =(C603/C602)-1 -> 0.0088888889 | N603: =(D603/D602)-1 -> 0.0047505938 | O603: =(E603/E602)-1 -> 0.010957324 | P603: =(F603/F602)-1 -> 0.0051282051
A604: 45076 | B604: 5.22 | C604: 4.46 | D604: 4.1 | E604: =NA() -> #N/A | F604: 3.81 | G604: =(B604-B603)/100 -> -0.0003 | H604: =(C604-C603)/100 -> -0.0008 | I604: =(D604-D603)/100 -> -0.0013 | J604: =(E604-E603)/100 -> #N/A | K604: =(F604-F603)/100 -> -0.0011 | L604: =(B604/B603)-1 -> -0.0057142857 | M604: =(C604/C603)-1 -> -0.017621145 | N604: =(D604/D603)-1 -> -0.030732861 | O604: =(E604/E603)-1 -> #N/A | P604: =(F604/F603)-1 -> -0.028061224
A605: 45077 | B605: 5.18 | C605: 4.4 | D605: 4.04 | E605: 3.9667 | F605: 3.74 | G605: =(B605-B604)/100 -> -0.0004 | H605: =(C605-C604)/100 -> -0.0006 | I605: =(D605-D604)/100 -> -0.0006 | J605: =(E605-E604)/100 -> #N/A | K605: =(F605-F604)/100 -> -0.0007 | L605: =(B605/B604)-1 -> -0.0076628352 | M605: =(C605/C604)-1 -> -0.013452915 | N605: =(D605/D604)-1 -> -0.014634146 | O605: =(E605/E604)-1 -> #N/A | P605: =(F605/F604)-1 -> -0.018372703
A606: 45078 | B606: 5.11 | C606: 4.33 | D606: 3.98 | E606: 3.8934 | F606: 3.7 | G606: =(B606-B605)/100 -> -0.0007 | H606: =(C606-C605)/100 -> -0.0007 | I606: =(D606-D605)/100 -> -0.0006 | J606: =(E606-E605)/100 -> -0.000733 | K606: =(F606-F605)/100 -> -0.0004 | L606: =(B606/B605)-1 -> -0.013513514 | M606: =(C606/C605)-1 -> -0.015909091 | N606: =(D606/D605)-1 -> -0.014851485 | O606: =(E606/E605)-1 -> -0.018478836 | P606: =(F606/F605)-1 -> -0.010695187
A607: 45079 | B607: 5.22 | C607: 4.5 | D607: 4.13 | E607: 3.8398 | F607: 3.84 | G607: =(B607-B606)/100 -> 0.0011 | H607: =(C607-C606)/100 -> 0.0017 | I607: =(D607-D606)/100 -> 0.0015 | J607: =(E607-E606)/100 -> -0.000536 | K607: =(F607-F606)/100 -> 0.0014 | L607: =(B607/B606)-1 -> 0.021526419 | M607: =(C607/C606)-1 -> 0.03926097 | N607: =(D607/D606)-1 -> 0.037688442 | O607: =(E607/E606)-1 -> -0.013766888 | P607: =(F607/F606)-1 -> 0.037837838
A608: 45082 | B608: 5.17 | C608: 4.46 | D608: 4.1 | E608: 3.931 | F608: 3.82 | G608: =(B608-B607)/100 -> -0.0005 | H608: =(C608-C607)/100 -> -0.0004 | I608: =(D608-D607)/100 -> -0.0003 | J608: =(E608-E607)/100 -> 0.000912 | K608: =(F608-F607)/100 -> -0.0002 | L608: =(B608/B607)-1 -> -0.0095785441 | M608: =(C608/C607)-1 -> -0.0088888889 | N608: =(D608/D607)-1 -> -0.0072639225 | O608: =(E608/E607)-1 -> 0.023751237 | P608: =(F608/F607)-1 -> -0.0052083333
A609: 45083 | B609: 5.2 | C609: 4.51 | D609: 4.15 | E609: 3.9351 | F609: 3.85 | G609: =(B609-B608)/100 -> 0.0003 | H609: =(C609-C608)/100 -> 0.0005 | I609: =(D609-D608)/100 -> 0.0005 | J609: =(E609-E608)/100 -> 4.1e-05 | K609: =(F609-F608)/100 -> 0.0003 | L609: =(B609/B608)-1 -> 0.0058027079 | M609: =(C609/C608)-1 -> 0.011210762 | N609: =(D609/D608)-1 -> 0.012195122 | O609: =(E609/E608)-1 -> 0.0010429916 | P609: =(F609/F608)-1 -> 0.0078534031
A610: 45084 | B610: 5.16 | C610: 4.56 | D610: 4.21 | E610: 3.9544 | F610: 3.93 | G610: =(B610-B609)/100 -> -0.0004 | H610: =(C610-C609)/100 -> 0.0005 | I610: =(D610-D609)/100 -> 0.0006 | J610: =(E610-E609)/100 -> 0.000193 | K610: =(F610-F609)/100 -> 0.0008 | L610: =(B610/B609)-1 -> -0.0076923077 | M610: =(C610/C609)-1 -> 0.011086475 | N610: =(D610/D609)-1 -> 0.014457831 | O610: =(E610/E609)-1 -> 0.0049045768 | P610: =(F610/F609)-1 -> 0.020779221
A611: 45085 | B611: 5.12 | C611: 4.52 | D611: 4.17 | E611: 4.0221 | F611: 3.87 | G611: =(B611-B610)/100 -> -0.0004 | H611: =(C611-C610)/100 -> -0.0004 | I611: =(D611-D610)/100 -> -0.0004 | J611: =(E611-E610)/100 -> 0.000677 | K611: =(F611-F610)/100 -> -0.0006 | L611: =(B611/B610)-1 -> -0.007751938 | M611: =(C611/C610)-1 -> -0.0087719298 | N611: =(D611/D610)-1 -> -0.0095011876 | O611: =(E611/E610)-1 -> 0.01712017 | P611: =(F611/F610)-1 -> -0.015267176
A612: 45086 | B612: 5.17 | C612: 4.59 | D612: 4.23 | E612: 3.9916 | F612: 3.92 | G612: =(B612-B611)/100 -> 0.0005 | H612: =(C612-C611)/100 -> 0.0007 | I612: =(D612-D611)/100 -> 0.0006 | J612: =(E612-E611)/100 -> -0.000305 | K612: =(F612-F611)/100 -> 0.0005 | L612: =(B612/B611)-1 -> 0.009765625 | M612: =(C612/C611)-1 -> 0.015486726 | N612: =(D612/D611)-1 -> 0.014388489 | O612: =(E612/E611)-1 -> -0.0075831034 | P612: =(F612/F611)-1 -> 0.012919897
A613: 45089 | B613: 5.18 | C613: 4.55 | D613: 4.16 | E613: 4.0272 | F613: 3.89 | G613: =(B613-B612)/100 -> 0.0001 | H613: =(C613-C612)/100 -> -0.0004 | I613: =(D613-D612)/100 -> -0.0007 | J613: =(E613-E612)/100 -> 0.000356 | K613: =(F613-F612)/100 -> -0.0003 | L613: =(B613/B612)-1 -> 0.001934236 | M613: =(C613/C612)-1 -> -0.0087145969 | N613: =(D613/D612)-1 -> -0.016548463 | O613: =(E613/E612)-1 -> 0.0089187293 | P613: =(F613/F612)-1 -> -0.0076530612
A614: 45090 | B614: 5.26 | C614: 4.67 | D614: 4.3 | E614: 4.0225 | F614: 4.01 | G614: =(B614-B613)/100 -> 0.0008 | H614: =(C614-C613)/100 -> 0.0012 | I614: =(D614-D613)/100 -> 0.0014 | J614: =(E614-E613)/100 -> -4.7e-05 | K614: =(F614-F613)/100 -> 0.0012 | L614: =(B614/B613)-1 -> 0.015444015 | M614: =(C614/C613)-1 -> 0.026373626 | N614: =(D614/D613)-1 -> 0.033653846 | O614: =(E614/E613)-1 -> -0.001167064 | P614: =(F614/F613)-1 -> 0.030848329
A615: 45091 | B615: 5.27 | C615: 4.74 | D615: 4.37 | E615: 4.1091 | F615: 4.06 | G615: =(B615-B614)/100 -> 0.0001 | H615: =(C615-C614)/100 -> 0.0007 | I615: =(D615-D614)/100 -> 0.0007 | J615: =(E615-E614)/100 -> 0.000866 | K615: =(F615-F614)/100 -> 0.0005 | L615: =(B615/B614)-1 -> 0.0019011407 | M615: =(C615/C614)-1 -> 0.014989293 | N615: =(D615/D614)-1 -> 0.01627907 | O615: =(E615/E614)-1 -> 0.0215289 | P615: =(F615/F614)-1 -> 0.012468828
A616: 45092 | B616: 5.21 | C616: 4.62 | D616: 4.23 | E616: 4.1583 | F616: 3.91 | G616: =(B616-B615)/100 -> -0.0006 | H616: =(C616-C615)/100 -> -0.0012 | I616: =(D616-D615)/100 -> -0.0014 | J616: =(E616-E615)/100 -> 0.000492 | K616: =(F616-F615)/100 -> -0.0015 | L616: =(B616/B615)-1 -> -0.011385199 | M616: =(C616/C615)-1 -> -0.025316456 | N616: =(D616/D615)-1 -> -0.032036613 | O616: =(E616/E615)-1 -> 0.011973425 | P616: =(F616/F615)-1 -> -0.036945813
... A618: 45097 | B618: 5.24 | C618: 4.68 | D618: 4.29 | E618: 4.1147 | F618: 3.96 | G618: =(B618-B617)/100 -> 0 | H618: =(C618-C617)/100 -> -0.0002 | I618: =(D618-D617)/100 -> -0.0003 | J618: =(E618-E617)/100 -> 0.000381 | K618: =(F618-F617)/100 -> -0.0003 | L618: =(B618/B617)-1 -> 0 | M618: =(C618/C617)-1 -> -0.0042553191 | N618: =(D618/D617)-1 -> -0.0069444444 | O618: =(E618/E617)-1 -> 0.0093460236 | P618: =(F618/F617)-1 -> -0.007518797
A619: 45098 | B619: 5.25 | C619: 4.68 | D619: 4.29 | E619: =NA() -> #N/A | F619: 3.95 | G619: =(B619-B618)/100 -> 0.0001 | H619: =(C619-C618)/100 -> 0 | I619: =(D619-D618)/100 -> 0 | J619: =(E619-E618)/100 -> #N/A | K619: =(F619-F618)/100 -> -0.0001 | L619: =(B619/B618)-1 -> 0.0019083969 | M619: =(C619/C618)-1 -> 0 | N619: =(D619/D618)-1 -> 0 | O619: =(E619/E618)-1 -> #N/A | P619: =(F619/F618)-1 -> -0.0025252525
A620: 45099 | B620: 5.29 | C620: 4.77 | D620: 4.37 | E620: 4.1085 | F620: 4.03 | G620: =(B620-B619)/100 -> 0.0004 | H620: =(C620-C619)/100 -> 0.0009 | I620: =(D620-D619)/100 -> 0.0008 | J620: =(E620-E619)/100 -> #N/A | K620: =(F620-F619)/100 -> 0.0008 | L620: =(B620/B619)-1 -> 0.0076190476 | M620: =(C620/C619)-1 -> 0.019230769 | N620: =(D620/D619)-1 -> 0.018648019 | O620: =(E620/E619)-1 -> #N/A | P620: =(F620/F619)-1 -> 0.020253165
A621: 45100 | B621: 5.25 | C621: 4.71 | D621: 4.32 | E621: 4.0994 | F621: 3.99 | G621: =(B621-B620)/100 -> -0.0004 | H621: =(C621-C620)/100 -> -0.0006 | I621: =(D621-D620)/100 -> -0.0005 | J621: =(E621-E620)/100 -> -9.1e-05 | K621: =(F621-F620)/100 -> -0.0004 | L621: =(B621/B620)-1 -> -0.0075614367 | M621: =(C621/C620)-1 -> -0.012578616 | N621: =(D621/D620)-1 -> -0.011441648 | O621: =(E621/E620)-1 -> -0.0022149203 | P621: =(F621/F620)-1 -> -0.0099255583
A622: 45103 | B622: 5.27 | C622: 4.65 | D622: 4.3 | E622: 4.1591 | F622: 3.96 | G622: =(B622-B621)/100 -> 0.0002 | H622: =(C622-C621)/100 -> -0.0006 | I622: =(D622-D621)/100 -> -0.0002 | J622: =(E622-E621)/100 -> 0.000597 | K622: =(F622-F621)/100 -> -0.0003 | L622: =(B622/B621)-1 -> 0.0038095238 | M622: =(C622/C621)-1 -> -0.012738854 | N622: =(D622/D621)-1 -> -0.0046296296 | O622: =(E622/E621)-1 -> 0.014563107 | P622: =(F622/F621)-1 -> -0.007518797
A623: 45104 | B623: 5.33 | C623: 4.74 | D623: 4.38 | E623: 4.1442 | F623: 4.02 | G623: =(B623-B622)/100 -> 0.0006 | H623: =(C623-C622)/100 -> 0.0009 | I623: =(D623-D622)/100 -> 0.0008 | J623: =(E623-E622)/100 -> -0.000149 | K623: =(F623-F622)/100 -> 0.0006 | L623: =(B623/B622)-1 -> 0.011385199 | M623: =(C623/C622)-1 -> 0.019354839 | N623: =(D623/D622)-1 -> 0.018604651 | O623: =(E623/E622)-1 -> -0.0035825058 | P623: =(F623/F622)-1 -> 0.015151515
A624: 45105 | B624: 5.32 | C624: 4.71 | D624: 4.32 | E624: 4.1258 | F624: 3.97 | G624: =(B624-B623)/100 -> -0.0001 | H624: =(C624-C623)/100 -> -0.0003 | I624: =(D624-D623)/100 -> -0.0006 | J624: =(E624-E623)/100 -> -0.000184 | K624: =(F624-F623)/100 -> -0.0005 | L624: =(B624/B623)-1 -> -0.0018761726 | M624: =(C624/C623)-1 -> -0.0063291139 | N624: =(D624/D623)-1 -> -0.01369863 | O624: =(E624/E623)-1 -> -0.0044399402 | P624: =(F624/F623)-1 -> -0.012437811
A625: 45106 | B625: 5.41 | C625: 4.87 | D625: 4.49 | E625: 4.1668 | F625: 4.14 | G625: =(B625-B624)/100 -> 0.0009 | H625: =(C625-C624)/100 -> 0.0016 | I625: =(D625-D624)/100 -> 0.0017 | J625: =(E625-E624)/100 -> 0.00041 | K625: =(F625-F624)/100 -> 0.0017 | L625: =(B625/B624)-1 -> 0.016917293 | M625: =(C625/C624)-1 -> 0.033970276 | N625: =(D625/D624)-1 -> 0.039351852 | O625: =(E625/E624)-1 -> 0.0099374667 | P625: =(F625/F624)-1 -> 0.042821159
A626: 45107 | B626: 5.4 | C626: 4.87 | D626: 4.49 | E626: 4.1367 | F626: 4.13 | G626: =(B626-B625)/100 -> -0.0001 | H626: =(C626-C625)/100 -> 0 | I626: =(D626-D625)/100 -> 0 | J626: =(E626-E625)/100 -> -0.000301 | K626: =(F626-F625)/100 -> -0.0001 | L626: =(B626/B625)-1 -> -0.0018484288 | M626: =(C626/C625)-1 -> 0 | N626: =(D626/D625)-1 -> 0 | O626: =(E626/E625)-1 -> -0.0072237688 | P626: =(F626/F625)-1 -> -0.0024154589
A627: 45110 | B627: 5.43 | C627: 4.94 | D627: 4.56 | E627: 4.2738 | F627: 4.19 | G627: =(B627-B626)/100 -> 0.0003 | H627: =(C627-C626)/100 -> 0.0007 | I627: =(D627-D626)/100 -> 0.0007 | J627: =(E627-E626)/100 -> 0.001371 | K627: =(F627-F626)/100 -> 0.0006 | L627: =(B627/B626)-1 -> 0.0055555556 | M627: =(C627/C626)-1 -> 0.014373717 | N627: =(D627/D626)-1 -> 0.0155902 | O627: =(E627/E626)-1 -> 0.03314236 | P627: =(F627/F626)-1 -> 0.014527845
...

Sheet Delta-Normal VaR
B2: Objective | C2: OPTION PORTFOLIO
L3: 1 | O3: 3 | S3: Insights
B4: long put | C4: NESTLE | D4: NESN | E4: 7000 | L4: σ | M4: {=SQRT((MMULT(MMULT(F11:G11,C11:D12),TRANSPOSE(F11:G11))))} -> 3657708.3 | O4: 1st percentile Return | P4: =_xlfn.PERCENTILE.INC(P18:P267,0.01) -> -0.51498906 | S4: The portfolio includes a long position in 7,000 NESN puts
B5: short call | C5: SWISS RE | D5: SREN | E5: 2000 | L5: VaR(99%,1) | M5: =_xlfn.NORM.S.INV(0.99)*M4 -> 8509101.9 | O5: VaR(99%,1) : | P5: =ABS(P4)*O17 -> 14536383 | S5: and a short position in 2,000 SREN calls, each referencing 1,000 shares.
L6: ES(99%,1) | M6: =M4*EXP(-(_xlfn.NORM.S.INV(0.99)^2)/2)/(SQRT(2*PI())*0.01) -> 9748576.1 | O6: Mean Below VaR : | P6: =AVERAGEIF(P18:P267,"<-0.514999") -> -0.63109505 | S6: Derived the 1-day risk measures:
I7: β_π | J7: σ_Market | O7: ES(99%,1) : | P7: =ABS(P6)*O17 -> 17813658 | S7: VaR(99%): CHF 14,536,382.70
I8: {=MMULT(I11:J11,Underlying_Assets!C3:C4)} -> 0.84408634 | J8: =SQRT(_xlfn.VAR.S(Underlying_Assets!K9:K295)) -> 0.0045202852 | L8: 2 | S8: ES(99%): CHF 17,813,658.16
L9: σ | M9: =SUM(F11:G11)*I8*J8 -> 1349876.7 | S9: This approach captures linear risk through deltas and provides
B10: VCV | C10: NESN | D10: SREN | F10: VALUE_NESN | G10: VALUE_SREN | I10: Weight_NESN | J10: Weight_SREN | L10: VaR(99%,1) | M10: =_xlfn.NORM.S.INV(0.99)*M9 -> 3140282.7 | S10: a fast approximation of market risk
B11: NESN | C11: =_xlfn.COVARIANCE.S(Underlying_Assets!H9:H365,Underlying_Assets!H9:H365) -> 0.00013124841 | D11: =_xlfn.COVARIANCE.S(Underlying_Assets!H9:H365,Underlying_Assets!I9:I365) -> 4.8345612e-05 | F11: =(I17-1)*Option_Portfolio!B4*1000*-1*C17 -> 2.5868236e+08 | G11: =(J17-1)*Option_Portfolio!B4*1000*-1*D17 -> 95104243 | I11: =F11/SUM($F$11:$G$11) -> 0.7311819 | J11: =G11/SUM($F$11:$G$11) -> 0.2688181 | L11: ES(99%,1) | M11: =M9*EXP(-(_xlfn.NORM.S.INV(0.99)^2)/2)/(SQRT(2*PI())*0.01) -> 3597710.5
B12: SREN | C12: =_xlfn.COVARIANCE.S(Underlying_Assets!I10:I366,Underlying_Assets!H10:H366) -> 4.8224643e-05 | D12: =_xlfn.COVARIANCE.S(Underlying_Assets!I10:I366,Underlying_Assets!I10:I366) -> 0.00024548163
B16: date | C16: P_NESN | D16: P_SREN | E16: d1_NESN | F16: d1_SREN | G16: d2_NESN | H16: d2_SREN | I16: N(d1)_NESN | J16: N(d1)_SREN | K16: N(d2)_NESN | L16: N(d2)_SREN | M16: Put_NESN | N16: Call_SREN | O16: π | P16: R_π
B17: 45407 | C17: 85.74 | D17: 144.8 | E17: =(LN(C17/Option_Portfolio!$E$4)+(Option_Portfolio!$H$4+0.5*Option_Portfolio!$G$4^2)*Option_Portfolio!$F$4)/(Option_Portfolio!$G$4*SQRT(Option_Portfolio!$F$4)) -> 0.17380855 | F17: =(LN(D17/Option_Portfolio!$E$5)+(Option_Portfolio!$H$5+0.5*Option_Portfolio!$G$5^2)*Option_Portfolio!$F$5)/(Option_Portfolio!$G$5*SQRT(Option_Portfolio!$F$5)) -> 1.3175439 | G17: =E17-Option_Portfolio!$G$4*SQRT(Option_Portfolio!$F$4) -> 0.053600397 | H17: =F17-Option_Portfolio!$G$5*SQRT(Option_Portfolio!$F$5) -> 1.1619805 | I17: =_xlfn.NORM.S.DIST(E17,TRUE) -> 0.56899204 | J17: =_xlfn.NORM.S.DIST(F17,TRUE) -> 0.90617182 | K17: =_xlfn.NORM.S.DIST(G17,TRUE) -> 0.52137323 | L17: =_xlfn.NORM.S.DIST(H17,TRUE) -> 0.8773783 | M17: =(1-K17)*Option_Portfolio!$E$4*EXP(-Option_Portfolio!$H$4*Option_Portfolio!$F$4)-(1-I17)*C17 -> 3.5257441 | N17: =J17*D17-L17*Option_Portfolio!$E$5*EXP(-Option_Portfolio!$H$5*Option_Portfolio!$F$5) -> 26.453397 | O17: =M17 * -Option_Portfolio!$B$4 * 1000 + N17 * Option_Portfolio!$B$5 * 1000 -> 28226585 | P17: 0
B18: T1 | C18: =$C$17*(1+Underlying_Assets!H9) -> 85.083217 | D18: =$D$17*(1+Underlying_Assets!I9) -> 143.15586 | E18: =(LN(C18/Option_Portfolio!$E$4)+(Option_Portfolio!$H$4+0.5*Option_Portfolio!$G$4^2)*Option_Portfolio!$F$4)/(Option_Portfolio!$G$4*SQRT(Option_Portfolio!$F$4)) -> 0.10983904 | F18: =(LN(D18/Option_Portfolio!$E$5)+(Option_Portfolio!$H$5+0.5*Option_Portfolio!$G$5^2)*Option_Portfolio!$F$5)/(Option_Portfolio!$G$5*SQRT(Option_Portfolio!$F$5)) -> 1.2441364 | G18: =E18-Option_Portfolio!$G$4*SQRT(Option_Portfolio!$F$4) -> -0.010369116 | H18: =F18-Option_Portfolio!$G$5*SQRT(Option_Portfolio!$F$5) -> 1.0885729 | I18: =_xlfn.NORM.S.DIST(E18,TRUE) -> 0.54373148 | J18: =_xlfn.NORM.S.DIST(F18,TRUE) -> 0.89327531 | K18: =_xlfn.NORM.S.DIST(G18,TRUE) -> 0.4958634 | L18: =_xlfn.NORM.S.DIST(H18,TRUE) -> 0.86182886 | M18: =(1-K18)*Option_Portfolio!$E$4*EXP(-Option_Portfolio!$H$4*Option_Portfolio!$F$4)-(1-I18)*C18 -> 3.8170948 | N18: =J18*D18-L18*Option_Portfolio!$E$5*EXP(-Option_Portfolio!$H$5*Option_Portfolio!$F$5) -> 24.973936 | O18: =M18 * -Option_Portfolio!$B$4 * 1000 + N18 * Option_Portfolio!$B$5 * 1000 -> 23228208 | P18: =(O18/O17)-1 -> -0.17708047
B19: T2 | C19: =$C$17*(1+Underlying_Assets!H10) -> 85.843146 | D19: =$D$17*(1+Underlying_Assets!I10) -> 144.56659 | E19: =(LN(C19/Option_Portfolio!$E$4)+(Option_Portfolio!$H$4+0.5*Option_Portfolio!$G$4^2)*Option_Portfolio!$F$4)/(Option_Portfolio!$G$4*SQRT(Option_Portfolio!$F$4)) -> 0.18381024 | F19: =(LN(D19/Option_Portfolio!$E$5)+(Option_Portfolio!$H$5+0.5*Option_Portfolio!$G$5^2)*Option_Portfolio!$F$5)/(Option_Portfolio!$G$5*SQRT(Option_Portfolio!$F$5)) -> 1.3071737 | G19: =E19-Option_Portfolio!$G$4*SQRT(Option_Portfolio!$F$4) -> 0.063602085 | H19: =F19-Option_Portfolio!$G$5*SQRT(Option_Portfolio!$F$5) -> 1.1516102 | I19: =_xlfn.NORM.S.DIST(E19,TRUE) -> 0.57291884 | J19: =_xlfn.NORM.S.DIST(F19,TRUE) -> 0.90442314 | K19: =_xlfn.NORM.S.DIST(G19,TRUE) -> 0.52535646 | L19: =_xlfn.NORM.S.DIST(H19,TRUE) -> 0.87525936 | M19: =(1-K19)*Option_Portfolio!$E$4*EXP(-Option_Portfolio!$H$4*Option_Portfolio!$F$4)-(1-I19)*C19 -> 3.48149 | N19: =J19*D19-L19*Option_Portfolio!$E$5*EXP(-Option_Portfolio!$H$5*Option_Portfolio!$F$5) -> 26.242093 | O19: =M19 * -Option_Portfolio!$B$4 * 1000 + N19 * Option_Portfolio!$B$5 * 1000 -> 28113757 | P19: =(O19/O18)-1 -> 0.21032826
B20: T3 | C20: =$C$17*(1+Underlying_Assets!H11) -> 85.525371 | D20: =$D$17*(1+Underlying_Assets!I11) -> 144.4201 | E20: =(LN(C20/Option_Portfolio!$E$4)+(Option_Portfolio!$H$4+0.5*Option_Portfolio!$G$4^2)*Option_Portfolio!$F$4)/(Option_Portfolio!$G$4*SQRT(Option_Portfolio!$F$4)) -> 0.15295811 | F20: =(LN(D20/Option_Portfolio!$E$5)+(Option_Portfolio!$H$5+0.5*Option_Portfolio!$G$5^2)*Option_Portfolio!$F$5)/(Option_Portfolio!$G$5*SQRT(Option_Portfolio!$F$5)) -> 1.3006566 | G20: =E20-Option_Portfolio!$G$4*SQRT(Option_Portfolio!$F$4) -> 0.032749959 | H20: =F20-Option_Portfolio!$G$5*SQRT(Option_Portfolio!$F$5) -> 1.1450931 | I20: =_xlfn.NORM.S.DIST(E20,TRUE) -> 0.56078435 | J20: =_xlfn.NORM.S.DIST(F20,TRUE) -> 0.90331198 | K20: =_xlfn.NORM.S.DIST(G20,TRUE) -> 0.51306301 | L20: =_xlfn.NORM.S.DIST(H20,TRUE) -> 0.8739147 | M20: =(1-K20)*Option_Portfolio!$E$4*EXP(-Option_Portfolio!$H$4*Option_Portfolio!$F$4)-(1-I20)*C20 -> 3.6191308 | N20: =J20*D20-L20*Option_Portfolio!$E$5*EXP(-Option_Portfolio!$H$5*Option_Portfolio!$F$5) -> 26.109684 | O20: =M20 * -Option_Portfolio!$B$4 * 1000 + N20 * Option_Portfolio!$B$5 * 1000 -> 26885452 | P20: =(O20/O19)-1 -> -0.043690516
B21: T4 | C21: =$C$17*(1+Underlying_Assets!H12) -> 85.266631 | D21: =$D$17*(1+Underlying_Assets!I12) -> 144.5949 | E21: =(LN(C21/Option_Portfolio!$E$4)+(Option_Portfolio!$H$4+0.5*Option_Portfolio!$G$4^2)*Option_Portfolio!$F$4)/(Option_Portfolio!$G$4*SQRT(Option_Portfolio!$F$4)) -> 0.1277528 | F21: =(LN(D21/Option_Portfolio!$E$5)+(Option_Portfolio!$H$5+0.5*Option_Portfolio!$G$5^2)*Option_Portfolio!$F$5)/(Option_Portfolio!$G$5*SQRT(Option_Portfolio!$F$5)) -> 1.3084323 | G21: =E21-Option_Portfolio!$G$4*SQRT(Option_Portfolio!$F$4) -> 0.0075446465 | H21: =F21-Option_Portfolio!$G$5*SQRT(Option_Portfolio!$F$5) -> 1.1528688 | I21: =_xlfn.NORM.S.DIST(E21,TRUE) -> 0.5508277 | J21: =_xlfn.NORM.S.DIST(F21,TRUE) -> 0.90463664 | K21: =_xlfn.NORM.S.DIST(G21,TRUE) -> 0.50300985 | L21: =_xlfn.NORM.S.DIST(H21,TRUE) -> 0.87551789 | M21: =(1-K21)*Option_Portfolio!$E$4*EXP(-Option_Portfolio!$H$4*Option_Portfolio!$F$4)-(1-I21)*C21 -> 3.7340601 | N21: =J21*D21-L21*Option_Portfolio!$E$5*EXP(-Option_Portfolio!$H$5*Option_Portfolio!$F$5) -> 26.267699 | O21: =M21 * -Option_Portfolio!$B$4 * 1000 + N21 * Option_Portfolio!$B$5 * 1000 -> 26396977 | P21: =(O21/O20)-1 -> -0.018168746
B22: T5 | C22: =$C$17*(1+Underlying_Assets!H13) -> 86.466977 | D22: =$D$17*(1+Underlying_Assets!I13) -> 144.3012 | E22: =(LN(C22/Option_Portfolio!$E$4)+(Option_Portfolio!$H$4+0.5*Option_Portfolio!$G$4^2)*Option_Portfolio!$F$4)/(Option_Portfolio!$G$4*SQRT(Option_Portfolio!$F$4)) -> 0.24404596 | F22: =(LN(D22/Option_Portfolio!$E$5)+(Option_Portfolio!$H$5+0.5*Option_Portfolio!$G$5^2)*Option_Portfolio!$F$5)/(Option_Portfolio!$G$5*SQRT(Option_Portfolio!$F$5)) -> 1.2953618 | G22: =E22-Option_Portfolio!$G$4*SQRT(Option_Portfolio!$F$4) -> 0.12383781 | H22: =F22-Option_Portfolio!$G$5*SQRT(Option_Portfolio!$F$5) -> 1.1397983 | I22: =_xlfn.NORM.S.DIST(E22,TRUE) -> 0.59640239 | J22: =_xlfn.NORM.S.DIST(F22,TRUE) -> 0.90240228 | K22: =_xlfn.NORM.S.DIST(G22,TRUE) -> 0.54927815 | L22: =_xlfn.NORM.S.DIST(H22,TRUE) -> 0.87281483 | M22: =(1-K22)*Option_Portfolio!$E$4*EXP(-Option_Portfolio!$H$4*Option_Portfolio!$F$4)-(1-I22)*C22 -> 3.222413 | N22: =J22*D22-L22*Option_Portfolio!$E$5*EXP(-Option_Portfolio!$H$5*Option_Portfolio!$F$5) -> 26.002329 | O22: =M22 * -Option_Portfolio!$B$4 * 1000 + N22 * Option_Portfolio!$B$5 * 1000 -> 29447768 | P22: =(O22/O21)-1 -> 0.11557348
B23: T6 | C23: =$C$17*(1+Underlying_Assets!H14) -> 85.285169 | D23: =$D$17*(1+Underlying_Assets!I14) -> 144.21114 | E23: =(LN(C23/Option_Portfolio!$E$4)+(Option_Portfolio!$H$4+0.5*Option_Portfolio!$G$4^2)*Option_Portfolio!$F$4)/(Option_Portfolio!$G$4*SQRT(Option_Portfolio!$F$4)) -> 0.12956118 | F23: =(LN(D23/Option_Portfolio!$E$5)+(Option_Portfolio!$H$5+0.5*Option_Portfolio!$G$5^2)*Option_Portfolio!$F$5)/(Option_Portfolio!$G$5*SQRT(Option_Portfolio!$F$5)) -> 1.291349 | G23: =E23-Option_Portfolio!$G$4*SQRT(Option_Portfolio!$F$4) -> 0.0093530271 | H23: =F23-Option_Portfolio!$G$5*SQRT(Option_Portfolio!$F$5) -> 1.1357855 | I23: =_xlfn.NORM.S.DIST(E23,TRUE) -> 0.55154319 | J23: =_xlfn.NORM.S.DIST(F23,TRUE) -> 0.90170865 | K23: =_xlfn.NORM.S.DIST(G23,TRUE) -> 0.50373126 | L23: =_xlfn.NORM.S.DIST(H23,TRUE) -> 0.87197682 | M23: =(1-K23)*Option_Portfolio!$E$4*EXP(-Option_Portfolio!$H$4*Option_Portfolio!$F$4)-(1-I23)*C23 -> 3.7257402 | N23: =J23*D23-L23*Option_Portfolio!$E$5*EXP(-Option_Portfolio!$H$5*Option_Portfolio!$F$5) -> 25.921097 | O23: =M23 * -Option_Portfolio!$B$4 * 1000 + N23 * Option_Portfolio!$B$5 * 1000 -> 25762012 | P23: =(O23/O22)-1 -> -0.12516248
B24: T7 | C24: =$C$17*(1+Underlying_Assets!H15) -> 85.32588 | D24: =$D$17*(1+Underlying_Assets!I15) -> 146.63291 | E24: =(LN(C24/Option_Portfolio!$E$4)+(Option_Portfolio!$H$4+0.5*Option_Portfolio!$G$4^2)*Option_Portfolio!$F$4)/(Option_Portfolio!$G$4*SQRT(Option_Portfolio!$F$4)) -> 0.13353135 | F24: =(LN(D24/Option_Portfolio!$E$5)+(Option_Portfolio!$H$5+0.5*Option_Portfolio!$G$5^2)*Option_Portfolio!$F$5)/(Option_Portfolio!$G$5*SQRT(Option_Portfolio!$F$5)) -> 1.3984034 | G24: =E24-Option_Portfolio!$G$4*SQRT(Option_Portfolio!$F$4) -> 0.013323199 | H24: =F24-Option_Portfolio!$G$5*SQRT(Option_Portfolio!$F$5) -> 1.2428399 | I24: =_xlfn.NORM.S.DIST(E24,TRUE) -> 0.55311341 | J24: =_xlfn.NORM.S.DIST(F24,TRUE) -> 0.91900402 | K24: =_xlfn.NORM.S.DIST(G24,TRUE) -> 0.50531503 | L24: =_xlfn.NORM.S.DIST(H24,TRUE) -> 0.89303659 | M24: =(1-K24)*Option_Portfolio!$E$4*EXP(-Option_Portfolio!$H$4*Option_Portfolio!$F$4)-(1-I24)*C24 -> 3.7075147 | N24: =J24*D24-L24*Option_Portfolio!$E$5*EXP(-Option_Portfolio!$H$5*Option_Portfolio!$F$5) -> 28.126329 | O24: =M24 * -Option_Portfolio!$B$4 * 1000 + N24 * Option_Portfolio!$B$5 * 1000 -> 30300056 | P24: =(O24/O23)-1 -> 0.17615255
B25: T8 | C25: =$C$17*(1+Underlying_Assets!H16) -> 86.173468 | D25: =$D$17*(1+Underlying_Assets!I16) -> 144.65403 | E25: =(LN(C25/Option_Portfolio!$E$4)+(Option_Portfolio!$H$4+0.5*Option_Portfolio!$G$4^2)*Option_Portfolio!$F$4)/(Option_Portfolio!$G$4*SQRT(Option_Portfolio!$F$4)) -> 0.21575974 | F25: =(LN(D25/Option_Portfolio!$E$5)+(Option_Portfolio!$H$5+0.5*Option_Portfolio!$G$5^2)*Option_Portfolio!$F$5)/(Option_Portfolio!$G$5*SQRT(Option_Portfolio!$F$5)) -> 1.3110606 | G25: =E25-Option_Portfolio!$G$4*SQRT(Option_Portfolio!$F$4) -> 0.095551587 | H25: =F25-Option_Portfolio!$G$5*SQRT(Option_Portfolio!$F$5) -> 1.1554971 | I25: =_xlfn.NORM.S.DIST(E25,TRUE) -> 0.58541248 | J25: =_xlfn.NORM.S.DIST(F25,TRUE) -> 0.90508135 | K25: =_xlfn.NORM.S.DIST(G25,TRUE) -> 0.53806164 | L25: =_xlfn.NORM.S.DIST(H25,TRUE) -> 0.87605654 | M25: =(1-K25)*Option_Portfolio!$E$4*EXP(-Option_Portfolio!$H$4*Option_Portfolio!$F$4)-(1-I25)*C25 -> 3.3424826 | N25: =J25*D25-L25*Option_Portfolio!$E$5*EXP(-Option_Portfolio!$H$5*Option_Portfolio!$F$5) -> 26.321204 | O25: =M25 * -Option_Portfolio!$B$4 * 1000 + N25 * Option_Portfolio!$B$5 * 1000 -> 29245031 | P25: =(O25/O24)-1 -> -0.034819247
B26: T9 | C26: =$C$17*(1+Underlying_Assets!H17) -> 85.912515 | D26: =$D$17*(1+Underlying_Assets!I17) -> 144.85845 | E26: =(LN(C26/Option_Portfolio!$E$4)+(Option_Portfolio!$H$4+0.5*Option_Portfolio!$G$4^2)*Option_Portfolio!$F$4)/(Option_Portfolio!$G$4*SQRT(Option_Portfolio!$F$4)) -> 0.19052997 | F26: =(LN(D26/Option_Portfolio!$E$5)+(Option_Portfolio!$H$5+0.5*Option_Portfolio!$G$5^2)*Option_Portfolio!$F$5)/(Option_Portfolio!$G$5*SQRT(Option_Portfolio!$F$5)) -> 1.3201381 | G26: =E26-Option_Portfolio!$G$4*SQRT(Option_Portfolio!$F$4) -> 0.070321816 | H26: =F26-Option_Portfolio!$G$5*SQRT(Option_Portfolio!$F$5) -> 1.1645746 | I26: =_xlfn.NORM.S.DIST(E26,TRUE) -> 0.57555307 | J26: =_xlfn.NORM.S.DIST(F26,TRUE) -> 0.90660554 | K26: =_xlfn.NORM.S.DIST(G26,TRUE) -> 0.52803124 | L26: =_xlfn.NORM.S.DIST(H26,TRUE) -> 0.87790438 | M26: =(1-K26)*Option_Portfolio!$E$4*EXP(-Option_Portfolio!$H$4*Option_Portfolio!$F$4)-(1-I26)*C26 -> 3.4519551 | N26: =J26*D26-L26*Option_Portfolio!$E$5*EXP(-Option_Portfolio!$H$5*Option_Portfolio!$F$5) -> 26.506372 | O26: =M26 * -Option_Portfolio!$B$4 * 1000 + N26 * Option_Portfolio!$B$5 * 1000 -> 28849058 | P26: =(O26/O25)-1 -> -0.013539854
B27: T10 | C27: =$C$17*(1+Underlying_Assets!H18) -> 84.904982 | D27: =$D$17*(1+Underlying_Assets!I18) -> 144.68316 | E27: =(LN(C27/Option_Portfolio!$E$4)+(Option_Portfolio!$H$4+0.5*Option_Portfolio!$G$4^2)*Option_Portfolio!$F$4)/(Option_Portfolio!$G$4*SQRT(Option_Portfolio!$F$4)) -> 0.092394025 | F27: =(LN(D27/Option_Portfolio!$E$5)+(Option_Portfolio!$H$5+0.5*Option_Portfolio!$G$5^2)*Option_Portfolio!$F$5)/(Option_Portfolio!$G$5*SQRT(Option_Portfolio!$F$5)) -> 1.3123546 | G27: =E27-Option_Portfolio!$G$4*SQRT(Option_Portfolio!$F$4) -> -0.027814128 | H27: =F27-Option_Portfolio!$G$5*SQRT(Option_Portfolio!$F$5) -> 1.1567912 | I27: =_xlfn.NORM.S.DIST(E27,TRUE) -> 0.53680751 | J27: =_xlfn.NORM.S.DIST(F27,TRUE) -> 0.90529975 | K27: =_xlfn.NORM.S.DIST(G27,TRUE) -> 0.4889052 | L27: =_xlfn.NORM.S.DIST(H27,TRUE) -> 0.87632115 | M27: =(1-K27)*Option_Portfolio!$E$4*EXP(-Option_Portfolio!$H$4*Option_Portfolio!$F$4)-(1-I27)*C27 -> 3.8990347 | N27: =J27*D27-L27*Option_Portfolio!$E$5*EXP(-Option_Portfolio!$H$5*Option_Portfolio!$F$5) -> 26.347566 | O27: =M27 * -Option_Portfolio!$B$4 * 1000 + N27 * Option_Portfolio!$B$5 * 1000 -> 25401890 | P27: =(O27/O26)-1 -> -0.11948979
B28: T11 | C28: =$C$17*(1+Underlying_Assets!H19) -> 86.052951 | D28: =$D$17*(1+Underlying_Assets!I19) -> 146.1448 | E28: =(LN(C28/Option_Portfolio!$E$4)+(Option_Portfolio!$H$4+0.5*Option_Portfolio!$G$4^2)*Option_Portfolio!$F$4)/(Option_Portfolio!$G$4*SQRT(Option_Portfolio!$F$4)) -> 0.20411731 | F28: =(LN(D28/Option_Portfolio!$E$5)+(Option_Portfolio!$H$5+0.5*Option_Portfolio!$G$5^2)*Option_Portfolio!$F$5)/(Option_Portfolio!$G$5*SQRT(Option_Portfolio!$F$5)) -> 1.3769695 | G28: =E28-Option_Portfolio!$G$4*SQRT(Option_Portfolio!$F$4) -> 0.083909156 | H28: =F28-Option_Portfolio!$G$5*SQRT(Option_Portfolio!$F$5) -> 1.221406 | I28: =_xlfn.NORM.S.DIST(E28,TRUE) -> 0.58086909 | J28: =_xlfn.NORM.S.DIST(F28,TRUE) -> 0.91573915 | K28: =_xlfn.NORM.S.DIST(G28,TRUE) -> 0.53343567 | L28: =_xlfn.NORM.S.DIST(H28,TRUE) -> 0.88903382 | M28: =(1-K28)*Option_Portfolio!$E$4*EXP(-Option_Portfolio!$H$4*Option_Portfolio!$F$4)-(1-I28)*C28 -> 3.3927209 | N28: =J28*D28-L28*Option_Portfolio!$E$5*EXP(-Option_Portfolio!$H$5*Option_Portfolio!$F$5) -> 27.678547 | O28: =M28 * -Option_Portfolio!$B$4 * 1000 + N28 * Option_Portfolio!$B$5 * 1000 -> 31608047 | P28: =(O28/O27)-1 -> 0.24431872
B29: T12 | C29: =$C$17*(1+Underlying_Assets!H20) -> 85.133696 | D29: =$D$17*(1+Underlying_Assets!I20) -> 146.20484 | E29: =(LN(C29/Option_Portfolio!$E$4)+(Option_Portfolio!$H$4+0.5*Option_Portfolio!$G$4^2)*Option_Portfolio!$F$4)/(Option_Portfolio!$G$4*SQRT(Option_Portfolio!$F$4)) -> 0.1147731 | F29: =(LN(D29/Option_Portfolio!$E$5)+(Option_Portfolio!$H$5+0.5*Option_Portfolio!$G$5^2)*Option_Portfolio!$F$5)/(Option_Portfolio!$G$5*SQRT(Option_Portfolio!$F$5)) -> 1.3796098 | G29: =E29-Option_Portfolio!$G$4*SQRT(Option_Portfolio!$F$4) -> -0.0054350529 | H29: =F29-Option_Portfolio!$G$5*SQRT(Option_Portfolio!$F$5) -> 1.2240463 | I29: =_xlfn.NORM.S.DIST(E29,TRUE) -> 0.54568751 | J29: =_xlfn.NORM.S.DIST(F29,TRUE) -> 0.91614659 | K29: =_xlfn.NORM.S.DIST(G29,TRUE) -> 0.49783174 | L29: =_xlfn.NORM.S.DIST(H29,TRUE) -> 0.88953262 | M29: =(1-K29)*Option_Portfolio!$E$4*EXP(-Option_Portfolio!$H$4*Option_Portfolio!$F$4)-(1-I29)*C29 -> 3.7941122 | N29: =J29*D29-L29*Option_Portfolio!$E$5*EXP(-Option_Portfolio!$H$5*Option_Portfolio!$F$5) -> 27.73354 | O29: =M29 * -Option_Portfolio!$B$4 * 1000 + N29 * Option_Portfolio!$B$5 * 1000 -> 28908294 | P29: =(O29/O28)-1 -> -0.085413474
... B267: T250 | C267: =$C$17*(1+Underlying_Assets!H258) -> 85.783424 | D267: =$D$17*(1+Underlying_Assets!I258) -> 149.93866 | E267: =(LN(C267/Option_Portfolio!$E$4)+(Option_Portfolio!$H$4+0.5*Option_Portfolio!$G$4^2)*Option_Portfolio!$F$4)/(Option_Portfolio!$G$4*SQRT(Option_Portfolio!$F$4)) -> 0.17802065 | F267: =(LN(D267/Option_Portfolio!$E$5)+(Option_Portfolio!$H$5+0.5*Option_Portfolio!$G$5^2)*Option_Portfolio!$F$5)/(Option_Portfolio!$G$5*SQRT(Option_Portfolio!$F$5)) -> 1.5417146 | G267: =E267-Option_Portfolio!$G$4*SQRT(Option_Portfolio!$F$4) -> 0.0578125 | H267: =F267-Option_Portfolio!$G$5*SQRT(Option_Portfolio!$F$5) -> 1.3861511 | I267: =_xlfn.NORM.S.DIST(E267,TRUE) -> 0.57064662 | J267: =_xlfn.NORM.S.DIST(F267,TRUE) -> 0.93842852 | K267: =_xlfn.NORM.S.DIST(G267,TRUE) -> 0.52305101 | L267: =_xlfn.NORM.S.DIST(H267,TRUE) -> 0.91714962 | M267: =(1-K267)*Option_Portfolio!$E$4*EXP(-Option_Portfolio!$H$4*Option_Portfolio!$F$4)-(1-I267)*C267 -> 3.5070641 | N267: =J267*D267-L267*Option_Portfolio!$E$5*EXP(-Option_Portfolio!$H$5*Option_Portfolio!$F$5) -> 31.197674 | O267: =M267 * -Option_Portfolio!$B$4 * 1000 + N267 * Option_Portfolio!$B$5 * 1000 -> 37845899 | P267: =(O267/O266)-1 -> 0.63435919

Sheet Fixed Income VaR
C2: FIXED INCOME PORTFOLIO | H2: 1
H3: π : | I3: =SUM(E10:E12) -> 4.2985939e+08
C4: bonds | D4: maturity in years | E4: annual coupon | L4: Insights
B5: A | C5: 2000000 | D5: 1 | E5: zero | F5: 0 | H5: 2 | L5: The fixed-income portfolio, primarily composed of USD-denominated government bonds, shows a 1-day VaR(99%) between $2.27M and $2.42M,
B6: B | C6: -1500000 | D6: 3 | E6: 5 | F6: 5 | H6: σ | I6: {=SQRT(MMULT(MMULT(C26:G26,_xlfn.ANCHORARRAY(C43)),TRANSPOSE(C26:G26)))} -> 978748.46 | L6: with the expected shortfall ranging from $2.61M to $5.45M, depending on the risk assessment method.
B7: C | C7: 4000000 | D7: 5 | E7: 2 | F7: 2 | H7: VaR(99%,1) | I7: =_xlfn.NORM.S.INV(0.99)*I6 -> 2276909.4 | L7: The historical simulation approach reveals slightly higher tail risk than the variance-covariance method, suggesting sensitivity to nonlinearities in yield changes.
H8: ES(99%,1) | I8: =I6*EXP(-(_xlfn.NORM.S.INV(0.99)^2)/2)/(SQRT(2*PI())*0.01) -> 2608574.3 | L8: The portfolio remains exposed mainly at the 5-year maturity due to concentration, indicating moderate risk under normal conditions,
C9: bond | D9: price | E9: value | L9: but significant potential losses under stress scenarios.
C10: 2000000 | D10: =100/(1+(TSIR!B1080/100)) -> 96.200096 | E10: =C10*D10 -> 1.9240019e+08 | H10: 3
C11: -1500000 | D11: =(F6/(1+(TSIR!D1080/100))) + (F6/(1+(TSIR!D1080/100))^2) + (F6+100/(1+(TSIR!D1080/100))^3) -> 103.98095 | E11: =C11*D11 -> -1.5597143e+08 | H11: 1st percentile Return : | I11: =_xlfn.PERCENTILE.INC(T17:T267,0.01) -> -0.0059874944
C12: 4000000 | D12: =(F7/(1+(TSIR!F1080/100)))+(F7/(1+(TSIR!F1080/100))^2)+(F7+100/(1+(TSIR!F1080/100))^3)+(F7/(1+(TSIR!F1080/100))^4)+(F7/(1+(TSIR!F1080/100))^5) -> 98.357655 | E12: =C12*D12 -> 3.9343062e+08 | H12: VaR(99%,1) : | I12: =ABS(S17*I11) -> 2416696.8
H13: Mean Below VaR : | I13: =AVERAGEIF(T17:T267,"<-0.0124") -> -0.013494974
H14: ES(99%,1) : | I14: =ABS(S17*I13) -> 5446896.1
M15: Years maturity | Q15: Price | S15: π | T15: π return
B16: T | C16: 1 | D16: 2 | E16: 3 | F16: 4 | G16: 5 | J16: date | K16: 1 | L16: 2 | M16: 3 | N16: 4 | O16: 5
B17: yT | C17: =TSIR!B1080 -> 3.95 | D17: =TSIR!C1080 -> 3.74 | E17: =TSIR!D1080 -> 3.76 | F17: =TSIR!E1080 -> 3.7865 | G17: =TSIR!F1080 -> 3.88 | J17: 45772 | K17: =TSIR!B1080 -> 3.95 | L17: =TSIR!C1080 -> 3.74 | M17: =TSIR!D1080 -> 3.76 | N17: =TSIR!E1080 -> 3.7865 | O17: =TSIR!F1080 -> 3.88 | P17: =100/(1+(K17/100)) -> 96.200096 | Q17: =$F$6 * ((1 - (1 + M17 / 100)^(-$D$6)) / (M17 / 100)) + 100 / (1 + M17 / 100)^$D$6 -> 103.45685 | R17: =$F$7*((1-(1+O17/100)^(-$D$7))/(O17/100)) + (100/(1+O17/100)^$D$7) -> 91.602285 | S17: =P17*$C$10+Q17*$C$11+R17*$C$12 -> 4.0362406e+08 | T17: 0
B18: MD | C18: =C16/(1+(C17/100)) -> 0.96200096 | D18: =D16/(1+(D17/100)) -> 1.9278967 | E18: =E16/(1+(E17/100)) -> 2.8912876 | F18: =F16/(1+(F17/100)) -> 3.8540658 | G18: =G16/(1+(G17/100)) -> 4.8132461 | J18: T1 | K18: =K17*((TSIR!B4/TSIR!B3)) -> 4.345 | L18: =L17*((TSIR!C4/TSIR!C3)) -> 4.0276923 | M18: =M17*((TSIR!D4/TSIR!D3)) -> 4.4235294 | N18: =N17*((TSIR!E4/TSIR!E3)) -> 4.3348446 | O18: =O17*((TSIR!F4/TSIR!F3)) -> 4.3905263 | P18: =100/(1+(K18/100)) -> 95.835929 | Q18: =$F$6 * ((1 - (1 + M18 / 100)^(-$D$6)) / ($M$17 / 100)) + 100 / (1 + M18 / 100)^$D$6 -> 104.01604 | R18: =$F$7*((1-(1+O18/100)^(-$D$7))/($O$17/100)) + (100/(1+O18/100)^$D$7) -> 90.632343 | S18: =P18*$C$10+Q18*$C$11+R18*$C$12 -> 3.9817716e+08 | T18: =(S18/S17)-1 -> -0.013494974
B19: σ | C19: =STDEV(TSIR!G831:G1080) -> 0.00044750374 | D19: =STDEV(TSIR!H831:H1080) -> 0.00059178106 | E19: =STDEV(TSIR!I831:I1080) -> 0.00060028052 | F19: =STDEV(TSIR!J831:J1080) -> 0.00048602164 | G19: =STDEV(TSIR!K831:K1080) -> 0.00060628886 | J19: T2 | K19: =K18*((TSIR!B5/TSIR!B4)) -> 4.345 | L19: =L18*((TSIR!C5/TSIR!C4)) -> 4.0276923 | M19: =M18*((TSIR!D5/TSIR!D4)) -> 4.8658824 | N19: =N18*((TSIR!E5/TSIR!E4)) -> 4.675673 | O19: =O18*((TSIR!F5/TSIR!F4)) -> 4.6968421 | P19: =100/(1+(K19/100)) -> 95.835929 | Q19: =$F$6*((1-(1+M19/100)^(-$D$6))/(M19/100))+($F$6+100)/(1+$M$17/100)^$D$6 -> 107.64438 | R19: =$F$7*((1-(1+O19/100)^(-$D$7))/(O19/100))+($F$7+100)/(1+$O$17/100)^$D$7 -> 93.053917 | S19: =P19*$C$10+Q19*$C$11+R19*$C$12 -> 4.0242096e+08 | T19: =(S19/S18)-1 -> 0.010658065
B20: V | C20: =C18*C19 -> 0.00043049903 | D20: =D18*D19 -> 0.0011408927 | E20: =E18*E19 -> 0.0017355836 | F20: =F18*F19 -> 0.0018731594 | G20: =G18*G19 -> 0.0029182175 | J20: T3 | K20: =K19*((TSIR!B6/TSIR!B5)) -> 3.95 | L20: =L19*((TSIR!C6/TSIR!C5)) -> 4.0276923 | M20: =M19*((TSIR!D6/TSIR!D5)) -> 5.3082353 | N20: =N19*((TSIR!E6/TSIR!E5)) -> 5.023772 | O20: =O19*((TSIR!F6/TSIR!F5)) -> 5.0031579 | P20: =100/(1+(K20/100)) -> 96.200096 | Q20: =$F$6*((1-(1+M20/100)^(-$D$6))/(M20/100))+($F$6+100)/(1+$M$17/100)^$D$6 -> 107.53182 | R20: =$F$7*((1-(1+O20/100)^(-$D$7))/(O20/100))+($F$7+100)/(1+$O$17/100)^$D$7 -> 92.980114 | S20: =P20*$C$10+Q20*$C$11+R20*$C$12 -> 4.0302292e+08 | T20: =(S20/S19)-1 -> 0.0014958313
B21: Pos A | C21: =C5*100 -> 200000000 | D21: 0 | E21: 0 | F21: 0 | G21: 0 | J21: T4 | K21: =K20*((TSIR!B7/TSIR!B6)) -> 3.95 | L21: =L20*((TSIR!C7/TSIR!C6)) -> 4.0276923 | M21: =M20*((TSIR!D7/TSIR!D6)) -> 4.8658824 | N21: =N20*((TSIR!E7/TSIR!E6)) -> 4.9564139 | O21: =O20*((TSIR!F7/TSIR!F6)) -> 5.1052632 | P21: =100/(1+(K21/100)) -> 96.200096 | Q21: =$F$6*((1-(1+M21/100)^(-$D$6))/(M21/100))+($F$6+100)/(1+$M$17/100)^$D$6 -> 107.64438 | R21: =$F$7*((1-(1+O21/100)^(-$D$7))/(O21/100))+($F$7+100)/(1+$O$17/100)^$D$7 -> 92.955732 | S21: =P21*$C$10+Q21*$C$11+R21*$C$12 -> 4.0275656e+08 | T21: =(S21/S20)-1 -> -0.00066090631
B22: Pos B | C22: =C6*F6 -> -7500000 | D22: =C6*F6 -> -7500000 | E22: =C6*F6+C6*100 -> -157500000 | F22: 0 | G22: 0 | J22: T5 | K22: =K21*((TSIR!B8/TSIR!B7)) -> 4.345 | L22: =L21*((TSIR!C8/TSIR!C7)) -> 4.0276923 | M22: =M21*((TSIR!D8/TSIR!D7)) -> 5.0870588 | N22: =N21*((TSIR!E8/TSIR!E7)) -> 5.0248847 | O22: =O21*((TSIR!F8/TSIR!F7)) -> 5.1052632 | P22: =100/(1+(K22/100)) -> 95.835929 | Q22: =$F$6*((1-(1+M22/100)^(-$D$6))/(M22/100))+($F$6+100)/(1+$M$17/100)^$D$6 -> 107.5879 | R22: =$F$7*((1-(1+O22/100)^(-$D$7))/(O22/100))+($F$7+100)/(1+$O$17/100)^$D$7 -> 92.955732 | S22: =P22*$C$10+Q22*$C$11+R22*$C$12 -> 4.0211293e+08 | T22: =(S22/S21)-1 -> -0.0015980497
B23: Pos C | C23: =C7*F7 -> 8000000 | D23: =C7*F7 -> 8000000 | E23: =C7*F7 -> 8000000 | F23: =C7*F7 -> 8000000 | G23: =IF(D7=5, C7*F7 + C7*100, C7*F7) -> 408000000 | J23: T6 | K23: =K22*((TSIR!B9/TSIR!B8)) -> 4.74 | L23: =L22*((TSIR!C9/TSIR!C8)) -> 4.0276923 | M23: =M22*((TSIR!D9/TSIR!D8)) -> 4.8658824 | N23: =N22*((TSIR!E9/TSIR!E8)) -> 4.8144116 | O23: =O22*((TSIR!F9/TSIR!F8)) -> 4.9010526 | P23: =100/(1+(K23/100)) -> 95.474508 | Q23: =$F$6*((1-(1+M23/100)^(-$D$6))/(M23/100))+($F$6+100)/(1+$M$17/100)^$D$6 -> 107.64438 | R23: =$F$7*((1-(1+O23/100)^(-$D$7))/(O23/100))+($F$7+100)/(1+$O$17/100)^$D$7 -> 93.004605 | S23: =P23*$C$10+Q23*$C$11+R23*$C$12 -> 4.0150087e+08 | T23: =(S23/S22)-1 -> -0.001522104
B24: πZCB | C24: =SUM(C21:C23) -> 200500000 | D24: =SUM(D21:D23) -> 500000 | E24: =SUM(E21:E23) -> -149500000 | F24: =SUM(F21:F23) -> 8000000 | G24: =SUM(G21:G23) -> 408000000 | J24: T7 | K24: =K23*((TSIR!B10/TSIR!B9)) -> 3.95 | L24: =L23*((TSIR!C10/TSIR!C9)) -> 4.6030769 | M24: =M23*((TSIR!D10/TSIR!D9)) -> 5.0870588 | N24: =N23*((TSIR!E10/TSIR!E9)) -> 4.956521 | O24: =O23*((TSIR!F10/TSIR!F9)) -> 5.0031579 | P24: =100/(1+(K24/100)) -> 96.200096 | Q24: =$F$6*((1-(1+M24/100)^(-$D$6))/(M24/100))+($F$6+100)/(1+$M$17/100)^$D$6 -> 107.5879 | R24: =$F$7*((1-(1+O24/100)^(-$D$7))/(O24/100))+($F$7+100)/(1+$O$17/100)^$D$7 -> 92.980114 | S24: =P24*$C$10+Q24*$C$11+R24*$C$12 -> 4.0293879e+08 | T24: =(S24/S23)-1 -> 0.003581364
B25: DF | C25: =1/(1+(C18/100))^C17 -> 0.96288872 | D25: =1/(1+(D18/100))^D17 -> 0.93107346 | E25: =1/(1+(E18/100))^E17 -> 0.89837251 | F25: =1/(1+(F18/100))^F17 -> 0.86658747 | G25: =1/(1+(G18/100))^G17 -> 0.83326906 | J25: T8 | K25: =K24*((TSIR!B11/TSIR!B10)) -> 3.95 | L25: =L24*((TSIR!C11/TSIR!C10)) -> 3.74 | M25: =M24*((TSIR!D11/TSIR!D10)) -> 4.4235294 | N25: =N24*((TSIR!E11/TSIR!E10)) -> 4.5411249 | O25: =O24*((TSIR!F11/TSIR!F10)) -> 4.6968421 | P25: =100/(1+(K25/100)) -> 96.200096 | Q25: =$F$6*((1-(1+M25/100)^(-$D$6))/(M25/100))+($F$6+100)/(1+$M$17/100)^$D$6 -> 107.75851 | R25: =$F$7*((1-(1+O25/100)^(-$D$7))/(O25/100))+($F$7+100)/(1+$O$17/100)^$D$7 -> 93.053917 | S25: =P25*$C$10+Q25*$C$11+R25*$C$12 -> 4.0297809e+08 | T25: =(S25/S24)-1 -> 9.7532673e-05
B26: x | C26: =C24*C25 -> 1.9305919e+08 | D26: =D24*D25 -> 465536.73 | E26: =E24*E25 -> -1.3430669e+08 | F26: =F24*F25 -> 6932699.7 | G26: =G24*G25 -> 3.3997378e+08 | J26: T9 | K26: =K25*((TSIR!B12/TSIR!B11)) -> 3.95 | L26: =L25*((TSIR!C12/TSIR!C11)) -> 4.0276923 | M26: =M25*((TSIR!D12/TSIR!D11)) -> 4.6447059 | N26: =N25*((TSIR!E12/TSIR!E11)) -> 4.5413851 | O26: =O25*((TSIR!F12/TSIR!F11)) -> 4.5947368 | P26: =100/(1+(K26/100)) -> 96.200096 | Q26: =$F$6*((1-(1+M26/100)^(-$D$6))/(M26/100))+($F$6+100)/(1+$M$17/100)^$D$6 -> 107.70124 | R26: =$F$7*((1-(1+O26/100)^(-$D$7))/(O26/100))+($F$7+100)/(1+$O$17/100)^$D$7 -> 93.078739 | S26: =P26*$C$10+Q26*$C$11+R26*$C$12 -> 4.0316328e+08 | T26: =(S26/S25)-1 -> 0.00045955224
J27: T10 | K27: =K26*((TSIR!B13/TSIR!B12)) -> 3.95 | L27: =L26*((TSIR!C13/TSIR!C12)) -> 3.74 | M27: =M26*((TSIR!D13/TSIR!D12)) -> 4.2023529 | N27: =N26*((TSIR!E13/TSIR!E12)) -> 4.404017 | O27: =O26*((TSIR!F13/TSIR!F12)) -> 4.5947368 | P27: =100/(1+(K27/100)) -> 96.200096 | Q27: =$F$6*((1-(1+M27/100)^(-$D$6))/(M27/100))+($F$6+100)/(1+$M$17/100)^$D$6 -> 107.81618 | R27: =$F$7*((1-(1+O27/100)^(-$D$7))/(O27/100))+($F$7+100)/(1+$O$17/100)^$D$7 -> 93.078739 | S27: =P27*$C$10+Q27*$C$11+R27*$C$12 -> 4.0299088e+08 | T27: =(S27/S26)-1 -> -0.00042763336
B28: Vector V | C28: 1y | D28: 2y | E28: 3y | F28: 4y | G28: 5y | J28: T11 | K28: =K27*((TSIR!B14/TSIR!B13)) -> 3.95 | L28: =L27*((TSIR!C14/TSIR!C13)) -> 3.74 | M28: =M27*((TSIR!D14/TSIR!D13)) -> 4.2023529 | N28: =N27*((TSIR!E14/TSIR!E13)) -> 4.4061613 | O28: =O27*((TSIR!F14/TSIR!F13)) -> 4.5947368 | P28: =100/(1+(K28/100)) -> 96.200096 | Q28: =$F$6*((1-(1+M28/100)^(-$D$6))/(M28/100))+($F$6+100)/(1+$M$17/100)^$D$6 -> 107.81618 | R28: =$F$7*((1-(1+O28/100)^(-$D$7))/(O28/100))+($F$7+100)/(1+$O$17/100)^$D$7 -> 93.078739 | S28: =P28*$C$10+Q28*$C$11+R28*$C$12 -> 4.0299088e+08 | T28: =(S28/S27)-1 -> 0
B29: {=TRANSPOSE(C28:G28)} -> 1y | C29: =C20 -> 0.00043049903 | D29: 0 | E29: 0 | F29: 0 | G29: 0 | J29: T12 | K29: =K28*((TSIR!B15/TSIR!B14)) -> 3.95 | L29: =L28*((TSIR!C15/TSIR!C14)) -> 3.74 | M29: =M28*((TSIR!D15/TSIR!D14)) -> 4.2023529 | N29: =N28*((TSIR!E15/TSIR!E14)) -> 4.3383045 | O29: =O28*((TSIR!F15/TSIR!F14)) -> 4.4926316 | P29: =100/(1+(K29/100)) -> 96.200096 | Q29: =$F$6*((1-(1+M29/100)^(-$D$6))/(M29/100))+($F$6+100)/(1+$M$17/100)^$D$6 -> 107.81618 | R29: =$F$7*((1-(1+O29/100)^(-$D$7))/(O29/100))+($F$7+100)/(1+$O$17/100)^$D$7 -> 93.103673 | S29: =P29*$C$10+Q29*$C$11+R29*$C$12 -> 4.0309061e+08 | T29: =(S29/S28)-1 -> 0.00024748694
B30: 2y | C30: 0 | D30: =D20 -> 0.0011408927 | E30: 0 | F30: 0 | G30: 0 | J30: T13 | K30: =K29*((TSIR!B16/TSIR!B15)) -> 3.95 | L30: =L29*((TSIR!C16/TSIR!C15)) -> 3.74 | M30: =M29*((TSIR!D16/TSIR!D15)) -> 3.76 | N30: =N29*((TSIR!E16/TSIR!E15)) -> 4.060444 | O30: =O29*((TSIR!F16/TSIR!F15)) -> 4.2884211 | P30: =100/(1+(K30/100)) -> 96.200096 | Q30: =$F$6*((1-(1+M30/100)^(-$D$6))/(M30/100))+($F$6+100)/(1+$M$17/100)^$D$6 -> 107.93274 | R30: =$F$7*((1-(1+O30/100)^(-$D$7))/(O30/100))+($F$7+100)/(1+$O$17/100)^$D$7 -> 93.153878 | S30: =P30*$C$10+Q30*$C$11+R30*$C$12 -> 4.0311659e+08 | T30: =(S30/S29)-1 -> 6.4436543e-05
B31: 3y | C31: 0 | D31: 0 | E31: =E20 -> 0.0017355836 | F31: 0 | G31: 0 | J31: T14 | K31: =K30*((TSIR!B17/TSIR!B16)) -> 3.555 | L31: =L30*((TSIR!C17/TSIR!C16)) -> 3.1646154 | M31: =M30*((TSIR!D17/TSIR!D16)) -> 3.9811765 | N31: =N30*((TSIR!E17/TSIR!E16)) -> 4.1263933 | O31: =O30*((TSIR!F17/TSIR!F16)) -> 4.2884211 | P31: =100/(1+(K31/100)) -> 96.567042 | Q31: =$F$6*((1-(1+M31/100)^(-$D$6))/(M31/100))+($F$6+100)/(1+$M$17/100)^$D$6 -> 107.87426 | R31: =$F$7*((1-(1+O31/100)^(-$D$7))/(O31/100))+($F$7+100)/(1+$O$17/100)^$D$7 -> 93.153878 | S31: =P31*$C$10+Q31*$C$11+R31*$C$12 -> 4.0393821e+08 | T31: =(S31/S30)-1 -> 0.0020381741
B32: 4y | C32: 0 | D32: 0 | E32: 0 | F32: =F20 -> 0.0018731594 | G32: 0 | J32: T15 | K32: =K31*((TSIR!B18/TSIR!B17)) -> 3.555 | L32: =L31*((TSIR!C18/TSIR!C17)) -> 3.4523077 | M32: =M31*((TSIR!D18/TSIR!D17)) -> 3.9811765 | N32: =N31*((TSIR!E18/TSIR!E17)) -> 4.0587579 | O32: =O31*((TSIR!F18/TSIR!F17)) -> 4.1863158 | P32: =100/(1+(K32/100)) -> 96.567042 | Q32: =$F$6*((1-(1+M32/100)^(-$D$6))/(M32/100))+($F$6+100)/(1+$M$17/100)^$D$6 -> 107.87426 | R32: =$F$7*((1-(1+O32/100)^(-$D$7))/(O32/100))+($F$7+100)/(1+$O$17/100)^$D$7 -> 93.17915 | S32: =P32*$C$10+Q32*$C$11+R32*$C$12 -> 4.040393e+08 | T32: =(S32/S31)-1 -> 0.00025026096
B33: 5y | C33: 0 | D33: 0 | E33: 0 | F33: 0 | G33: =G20 -> 0.0029182175 | J33: T16 | K33: =K32*((TSIR!B19/TSIR!B18)) -> 3.16 | L33: =L32*((TSIR!C19/TSIR!C18)) -> 3.4523077 | M33: =M32*((TSIR!D19/TSIR!D18)) -> 3.9811765 | N33: =N32*((TSIR!E19/TSIR!E18)) -> 4.1289343 | O33: =O32*((TSIR!F19/TSIR!F18)) -> 4.2884211 | P33: =100/(1+(K33/100)) -> 96.936797 | Q33: =$F$6*((1-(1+M33/100)^(-$D$6))/(M33/100))+($F$6+100)/(1+$M$17/100)^$D$6 -> 107.87426 | R33: =$F$7*((1-(1+O33/100)^(-$D$7))/(O33/100))+($F$7+100)/(1+$O$17/100)^$D$7 -> 93.153878 | S33: =P33*$C$10+Q33*$C$11+R33*$C$12 -> 4.0467772e+08 | T33: =(S33/S32)-1 -> 0.0015800966
J34: T17 | K34: =K33*((TSIR!B20/TSIR!B19)) -> 3.95 | L34: =L33*((TSIR!C20/TSIR!C19)) -> 3.1646154 | M34: =M33*((TSIR!D20/TSIR!D19)) -> 4.2023529 | N34: =N33*((TSIR!E20/TSIR!E19)) -> 4.4059919 | O34: =O33*((TSIR!F20/TSIR!F19)) -> 4.5947368 | P34: =100/(1+(K34/100)) -> 96.200096 | Q34: =$F$6*((1-(1+M34/100)^(-$D$6))/(M34/100))+($F$6+100)/(1+$M$17/100)^$D$6 -> 107.81618 | R34: =$F$7*((1-(1+O34/100)^(-$D$7))/(O34/100))+($F$7+100)/(1+$O$17/100)^$D$7 -> 93.078739 | S34: =P34*$C$10+Q34*$C$11+R34*$C$12 -> 4.0299088e+08 | T34: =(S34/S33)-1 -> -0.004168358
B35: R_Changes | C35: 1y | D35: 2y | E35: 3y | F35: 4y | G35: 5y | J35: T18 | K35: =K34*((TSIR!B21/TSIR!B20)) -> 3.16 | L35: =L34*((TSIR!C21/TSIR!C20)) -> 3.1646154 | M35: =M34*((TSIR!D21/TSIR!D20)) -> 3.76 | N35: =N34*((TSIR!E21/TSIR!E20)) -> 4.0617227 | O35: =O34*((TSIR!F21/TSIR!F20)) -> 4.2884211 | P35: =100/(1+(K35/100)) -> 96.936797 | Q35: =$F$6*((1-(1+M35/100)^(-$D$6))/(M35/100))+($F$6+100)/(1+$M$17/100)^$D$6 -> 107.93274 | R35: =$F$7*((1-(1+O35/100)^(-$D$7))/(O35/100))+($F$7+100)/(1+$O$17/100)^$D$7 -> 93.153878 | S35: =P35*$C$10+Q35*$C$11+R35*$C$12 -> 4.0458999e+08 | T35: =(S35/S34)-1 -> 0.0039681066
B36: {=TRANSPOSE(C35:G35)} -> 1y | C36: =CORREL(TSIR!G831:G1080,TSIR!G831:G1080) -> 1 | D36: =CORREL(TSIR!G831:G1080,TSIR!H831:H1080) -> 0.90791142 | E36: =CORREL(TSIR!G831:G1080,TSIR!I831:I1080) -> 0.86685153 | F36: =CORREL(TSIR!G831:G1080,TSIR!J831:J1080) -> 0.8174392 | G36: =CORREL(TSIR!G831:G1080,TSIR!K831:K1080) -> 0.80107858 | J36: T19 | K36: =K35*((TSIR!B22/TSIR!B21)) -> 3.16 | L36: =L35*((TSIR!C22/TSIR!C21)) -> 3.1646154 | M36: =M35*((TSIR!D22/TSIR!D21)) -> 3.9811765 | N36: =N35*((TSIR!E22/TSIR!E21)) -> 4.337938 | O36: =O35*((TSIR!F22/TSIR!F21)) -> 4.5947368 | P36: =100/(1+(K36/100)) -> 96.936797 | Q36: =$F$6*((1-(1+M36/100)^(-$D$6))/(M36/100))+($F$6+100)/(1+$M$17/100)^$D$6 -> 107.87426 | R36: =$F$7*((1-(1+O36/100)^(-$D$7))/(O36/100))+($F$7+100)/(1+$O$17/100)^$D$7 -> 93.078739 | S36: =P36*$C$10+Q36*$C$11+R36*$C$12 -> 4.0437716e+08 | T36: =(S36/S35)-1 -> -0.00052602343
B37: 2y | C37: =CORREL(TSIR!H744:H993,TSIR!G744:G993) -> 0.90862351 | D37: =CORREL(TSIR!H831:H1080,TSIR!H831:H1080) -> 1 | E37: =CORREL(TSIR!H831:H1080,TSIR!I831:I1080) -> 0.94728722 | F37: =CORREL(TSIR!H831:H1080,TSIR!J831:J1080) -> 0.89139759 | G37: =CORREL(TSIR!H831:H1080,TSIR!K831:K1080) -> 0.909464 | J37: T20 | K37: =K36*((TSIR!B23/TSIR!B22)) -> 3.16 | L37: =L36*((TSIR!C23/TSIR!C22)) -> 3.1646154 | M37: =M36*((TSIR!D23/TSIR!D22)) -> 4.2023529 | N37: =N36*((TSIR!E23/TSIR!E22)) -> 4.4736 | O37: =O36*((TSIR!F23/TSIR!F22)) -> 4.6968421 | P37: =100/(1+(K37/100)) -> 96.936797 | Q37: =$F$6*((1-(1+M37/100)^(-$D$6))/(M37/100))+($F$6+100)/(1+$M$17/100)^$D$6 -> 107.81618 | R37: =$F$7*((1-(1+O37/100)^(-$D$7))/(O37/100))+($F$7+100)/(1+$O$17/100)^$D$7 -> 93.053917 | S37: =P37*$C$10+Q37*$C$11+R37*$C$12 -> 4.0436499e+08 | T37: =(S37/S36)-1 -> -3.0104251e-05
B38: 3y | C38: =CORREL(TSIR!I831:I1080,TSIR!G831:G1080) -> 0.86685153 | D38: =CORREL(TSIR!I831:I1080,TSIR!H831:H1080) -> 0.94728722 | E38: =CORREL(TSIR!B831:B1080,TSIR!B831:B1080) -> 1 | F38: =CORREL(TSIR!I831:I1080,TSIR!J831:J1080) -> 0.93224196 | G38: =CORREL(TSIR!I831:I1080,TSIR!K831:K1080) -> 0.95054192 | J38: T21 | K38: =K37*((TSIR!B24/TSIR!B23)) -> 2.765 | L38: =L37*((TSIR!C24/TSIR!C23)) -> 3.1646154 | M38: =M37*((TSIR!D24/TSIR!D23)) -> 3.9811765 | N38: =N37*((TSIR!E24/TSIR!E23)) -> 4.4057637 | O38: =O37*((TSIR!F24/TSIR!F23)) -> 4.6968421 | P38: =100/(1+(K38/100)) -> 97.309395 | Q38: =$F$6*((1-(1+M38/100)^(-$D$6))/(M38/100))+($F$6+100)/(1+$M$17/100)^$D$6 -> 107.87426 | R38: =$F$7*((1-(1+O38/100)^(-$D$7))/(O38/100))+($F$7+100)/(1+$O$17/100)^$D$7 -> 93.053917 | S38: =P38*$C$10+Q38*$C$11+R38*$C$12 -> 4.0502307e+08 | T38: =(S38/S37)-1 -> 0.001627443
B39: 4y | C39: =CORREL(TSIR!J831:J1080,TSIR!G831:G1080) -> 0.8174392 | D39: =CORREL(TSIR!J831:J1080,TSIR!H831:H1080) -> 0.89139759 | E39: =CORREL(TSIR!J831:J1080,TSIR!I831:I1080) -> 0.93224196 | F39: =CORREL(TSIR!J831:J1080,TSIR!J831:J1080) -> 1 | G39: =CORREL(TSIR!J831:J1080,TSIR!K831:K1080) -> 0.96271997 | J39: T22 | K39: =K38*((TSIR!B25/TSIR!B24)) -> 2.37 | L39: =L38*((TSIR!C25/TSIR!C24)) -> 2.5892308 | M39: =M38*((TSIR!D25/TSIR!D24)) -> 4.2023529 | N39: =N38*((TSIR!E25/TSIR!E24)) -> 4.5432257 | O39: =O38*((TSIR!F25/TSIR!F24)) -> 4.7989474 | P39: =100/(1+(K39/100)) -> 97.684869 | Q39: =$F$6*((1-(1+M39/100)^(-$D$6))/(M39/100))+($F$6+100)/(1+$M$17/100)^$D$6 -> 107.81618 | R39: =$F$7*((1-(1+O39/100)^(-$D$7))/(O39/100))+($F$7+100)/(1+$O$17/100)^$D$7 -> 93.029206 | S39: =P39*$C$10+Q39*$C$11+R39*$C$12 -> 4.0576229e+08 | T39: =(S39/S38)-1 -> 0.0018251236
B40: 5y | C40: =CORREL(TSIR!K831:K1080,TSIR!G831:G1080) -> 0.80107858 | D40: =CORREL(TSIR!K831:K1080,TSIR!H831:H1080) -> 0.909464 | E40: =CORREL(TSIR!K831:K1080,TSIR!I831:I1080) -> 0.95054192 | F40: =CORREL(TSIR!K831:K1080,TSIR!J831:J1080) -> 0.96271997 | G40: =CORREL(TSIR!K831:K1080,TSIR!K831:K1080) -> 1 | J40: T23 | K40: =K39*((TSIR!B26/TSIR!B25)) -> 2.765 | L40: =L39*((TSIR!C26/TSIR!C25)) -> 3.1646154 | M40: =M39*((TSIR!D26/TSIR!D25)) -> 4.4235294 | N40: =N39*((TSIR!E26/TSIR!E25)) -> 4.6783703 | O40: =O39*((TSIR!F26/TSIR!F25)) -> 4.9010526 | P40: =100/(1+(K40/100)) -> 97.309395 | Q40: =$F$6*((1-(1+M40/100)^(-$D$6))/(M40/100))+($F$6+100)/(1+$M$17/100)^$D$6 -> 107.75851 | R40: =$F$7*((1-(1+O40/100)^(-$D$7))/(O40/100))+($F$7+100)/(1+$O$17/100)^$D$7 -> 93.004605 | S40: =P40*$C$10+Q40*$C$11+R40*$C$12 -> 4.0499944e+08 | T40: =(S40/S39)-1 -> -0.0018800295
J41: T24 | K41: =K40*((TSIR!B27/TSIR!B26)) -> 2.765 | L41: =L40*((TSIR!C27/TSIR!C26)) -> 3.1646154 | M41: =M40*((TSIR!D27/TSIR!D26)) -> 4.2023529 | N41: =N40*((TSIR!E27/TSIR!E26)) -> 4.6083092 | O41: =O40*((TSIR!F27/TSIR!F26)) -> 4.9010526 | P41: =100/(1+(K41/100)) -> 97.309395 | Q41: =$F$6*((1-(1+M41/100)^(-$D$6))/(M41/100))+($F$6+100)/(1+$M$17/100)^$D$6 -> 107.81618 | R41: =$F$7*((1-(1+O41/100)^(-$D$7))/(O41/100))+($F$7+100)/(1+$O$17/100)^$D$7 -> 93.004605 | S41: =P41*$C$10+Q41*$C$11+R41*$C$12 -> 4.0491294e+08 | T41: =(S41/S40)-1 -> -0.00021359319
...

Sheet Total Fund Risk
B2: TOTAL FUND RISK | I2: 1
I3: 1st percentile Return : | J3: =_xlfn.PERCENTILE.INC(F19:F268,0.01) -> -0.034943796
I4: VaR(99%,1) : | J4: =ABS(J3)*E18 -> 15090501
B5: Insights | I5: Mean Below VaR : | J5: =AVERAGEIF(F19:F268,"<-0.0394") -> -0.05874482
B6: The VaR(99%,1) estimates a potential one-day loss of CHF 15–17 million with 99% confidence, | I6: ES(99%,1) : | J6: =ABS(J5*E18) -> 25368989
B7: while ES(99%,1) shows that if losses exceed VaR, they average CHF 23–25 million.
B8: This reflects a left-skewed distribution with considerable tail risk, | I8: 2
B9: which should be closely monitored under stressed conditions | I9: 1st percentile Return : | J9: =_xlfn.PERCENTILE.INC(K19:K268,0.01) -> -0.043851558
I10: VaR(99%,1) : | J10: =ABS(J9)*J18 -> 16835500
I11: Mean Below VaR : | J11: =AVERAGEIF(K19:K268,"<-0.04385") -> -0.059415977
I12: ES(99%,1) : | J12: =ABS(J11)*J18 -> 22810995
B17: date | C17: π_Options | D17: π_FI (USD) | E17: π (Mixed) | F17: R_π (Mixed) | H17: CHF/USD | I17: π_FI | J17: π | K17: R_π (CHF) | O17: Total VaR (CHF)
B18: 45772 | C18: 28226585 | D18: 4.0362406e+08 | E18: =C18+D18 -> 4.3185065e+08 | F18: 0 | H18: 1.134752 | I18: =D18/H18 -> 3.5569363e+08 | J18: =C18+I18 -> 3.8392022e+08 | K18: 0 | O18: =SQRT(15090501^2 + (2276909 * 1.105)^2 + 2 * 0 * 15090501 * (2276909 * 1.105)) -> 15298804
